Workbook

Sheet Invoice Tracker
A1: Invoice ID | B1: Vendor Name | C1: Invoice Number | D1: Invoice Amount | E1: Department | F1: Invoice Type | G1: PO Number | H1: Approver | I1: Approval Level | J1: Date Received | K1: Payment Terms | L1: Payment Due Date | M1: Status | N1: Exception Type | O1: Approval Date | P1: Payment Date | Q1: Invoice Age Days | R1: Approval Cycle Days | S1: Days Until Due | T1: Overdue Approval Flag | U1: Late Payment Risk | V1: Comments
A2: NS-202606-0001 | B2: Union Energy Services | C2: INV-343962 | D2: 1501.38 | E2: Maintenance | F2: PO | G2: PO-78265 | H2: Marcus Lee | I2: Department Manager | J2: 46150 | K2: Net 15 | L2: 46165 | M2: Paid | N2: None | O2: 46152 | P2: 46154 | Q2: =IF(J2="","",TODAY()-J2) -> 39 | R2: =IF(O2="","",O2-J2) -> 2 | S2: =IF(L2="","",L2-TODAY()) -> -24 | T2: =IF(AND(M2="Pending Approval",Q2>5),"Overdue","On Track") -> On Track | U2: =IF(AND(M2<>"Paid",S2<=5),"At Risk","Normal") -> Normal | V2: Payment completed
A3: NS-202606-0002 | B3: Quarry Equipment Rental | C3: INV-456778 | D3: 1154.71 | E3: HR | F3: Non-PO | H3: Ava Johnson | I3: Department Manager | J3: 46178 | K3: 2/10 Net 30 | L3: 46208 | M3: Pending Approval | N3: None | Q3: =IF(J3="","",TODAY()-J3) -> 11 | R3: =IF(O3="","",O3-J3) | S3: =IF(L3="","",L3-TODAY()) -> 19 | T3: =IF(AND(M3="Pending Approval",Q3>5),"Overdue","On Track") -> Overdue | U3: =IF(AND(M3<>"Paid",S3<=5),"At Risk","Normal") -> Normal | V3: Awaiting manager/director action
A4: NS-202606-0003 | B4: IronGate Components | C4: INV-662275 | D4: 3723.9 | E4: Procurement | F4: PO | G4: PO-54898 | H4: Nina Patel | I4: Department Manager | J4: 46150 | K4: Net 45 | L4: 46195 | M4: Paid | N4: Missing Documentation | O4: 46164 | P4: 46168 | Q4: =IF(J4="","",TODAY()-J4) -> 39 | R4: =IF(O4="","",O4-J4) -> 14 | S4: =IF(L4="","",L4-TODAY()) -> 6 | T4: =IF(AND(M4="Pending Approval",Q4>5),"Overdue","On Track") -> On Track | U4: =IF(AND(M4<>"Paid",S4<=5),"At Risk","Normal") -> Normal | V4: Exception review required: Missing Documentation
A5: NS-202606-0004 | B5: Delta Tooling | C5: INV-498591 | D5: 1583.96 | E5: Engineering | F5: Non-PO | H5: Maya Singh | I5: Department Manager | J5: 46167 | K5: Net 30 | L5: 46197 | M5: Paid | N5: Missing PO | O5: 46182 | P5: 46183 | Q5: =IF(J5="","",TODAY()-J5) -> 22 | R5: =IF(O5="","",O5-J5) -> 15 | S5: =IF(L5="","",L5-TODAY()) -> 8 | T5: =IF(AND(M5="Pending Approval",Q5>5),"Overdue","On Track") -> On Track | U5: =IF(AND(M5<>"Paid",S5<=5),"At Risk","Normal") -> Normal | V5: Exception review required: Missing PO
A6: NS-202606-0005 | B6: IronGate Components | C6: INV-279451 | D6: 1909.99 | E6: Facilities | F6: PO | G6: PO-43730 | H6: Grace Morgan | I6: Department Manager | J6: 46186 | K6: Net 45 | L6: 46231 | M6: Exception | N6: None | Q6: =IF(J6="","",TODAY()-J6) -> 3 | R6: =IF(O6="","",O6-J6) | S6: =IF(L6="","",L6-TODAY()) -> 42 | T6: =IF(AND(M6="Pending Approval",Q6>5),"Overdue","On Track") -> On Track | U6: =IF(AND(M6<>"Paid",S6<=5),"At Risk","Normal") -> Normal
A7: NS-202606-0006 | B7: Ridgeway Plastics | C7: INV-133659 | D7: 2353.28 | E7: Sales | F7: PO | G7: PO-71943 | H7: Ryan Scott | I7: Department Manager | J7: 46188 | K7: Net 30 | L7: 46218 | M7: Pending Approval | N7: None | Q7: =IF(J7="","",TODAY()-J7) -> 1 | R7: =IF(O7="","",O7-J7) | S7: =IF(L7="","",L7-TODAY()) -> 29 | T7: =IF(AND(M7="Pending Approval",Q7>5),"Overdue","On Track") -> On Track | U7: =IF(AND(M7<>"Paid",S7<=5),"At Risk","Normal") -> Normal | V7: Awaiting manager/director action
A8: NS-202606-0007 | B8: Keystone Electrical | C8: INV-358607 | D8: 1209.97 | E8: Engineering | F8: Non-PO | H8: Maya Singh | I8: Department Manager | J8: 46189 | K8: Net 45 | L8: 46234 | M8: Pending Approval | N8: None | Q8: =IF(J8="","",TODAY()-J8) -> 0 | R8: =IF(O8="","",O8-J8) | S8: =IF(L8="","",L8-TODAY()) -> 45 | T8: =IF(AND(M8="Pending Approval",Q8>5),"Overdue","On Track") -> On Track | U8: =IF(AND(M8<>"Paid",S8<=5),"At Risk","Normal") -> Normal | V8: Awaiting manager/director action
A9: NS-202606-0008 | B9: Zenith Software | C9: INV-892495 | D9: 3648.91 | E9: IT | F9: PO | G9: PO-68242 | H9: Noah Bennett | I9: Department Manager | J9: 46169 | K9: Net 45 | L9: 46214 | M9: Paid | N9: None | O9: 46172 | P9: 46173 | Q9: =IF(J9="","",TODAY()-J9) -> 20 | R9: =IF(O9="","",O9-J9) -> 3 | S9: =IF(L9="","",L9-TODAY()) -> 25 | T9: =IF(AND(M9="Pending Approval",Q9>5),"Overdue","On Track") -> On Track | U9: =IF(AND(M9<>"Paid",S9<=5),"At Risk","Normal") -> Normal | V9: Payment completed
A10: NS-202606-0009 | B10: BlueLine Logistics | C10: INV-813328 | D10: 977.92 | E10: Maintenance | F10: Non-PO | H10: Marcus Lee | I10: Department Manager | J10: 46182 | K10: Net 15 | L10: 46197 | M10: Rejected | N10: None | O10: 46184 | Q10: =IF(J10="","",TODAY()-J10) -> 7 | R10: =IF(O10="","",O10-J10) -> 2 | S10: =IF(L10="","",L10-TODAY()) -> 8 | T10: =IF(AND(M10="Pending Approval",Q10>5),"Overdue","On Track") -> On Track | U10: =IF(AND(M10<>"Paid",S10<=5),"At Risk","Normal") -> Normal
A11: NS-202606-0010 | B11: Zenith Software | C11: INV-854639 | D11: 2693.22 | E11: Maintenance | F11: PO | G11: PO-72006 | H11: Marcus Lee | I11: Department Manager | J11: 46165 | K11: Net 15 | L11: 46180 | M11: Paid | N11: None | O11: 46170 | P11: 46176 | Q11: =IF(J11="","",TODAY()-J11) -> 24 | R11: =IF(O11="","",O11-J11) -> 5 | S11: =IF(L11="","",L11-TODAY()) -> -9 | T11: =IF(AND(M11="Pending Approval",Q11>5),"Overdue","On Track") -> On Track | U11: =IF(AND(M11<>"Paid",S11<=5),"At Risk","Normal") -> Normal | V11: Payment completed
A12: NS-202606-0011 | B12: IronGate Components | C12: INV-656116 | D12: 14899.79 | E12: IT | F12: PO | G12: PO-70979 | H12: Monica Price | I12: Director | J12: 46163 | K12: Net 30 | L12: 46193 | M12: Paid | N12: None | O12: 46166 | P12: 46173 | Q12: =IF(J12="","",TODAY()-J12) -> 26 | R12: =IF(O12="","",O12-J12) -> 3 | S12: =IF(L12="","",L12-TODAY()) -> 4 | T12: =IF(AND(M12="Pending Approval",Q12>5),"Overdue","On Track") -> On Track | U12: =IF(AND(M12<>"Paid",S12<=5),"At Risk","Normal") -> Normal | V12: Payment completed
A13: NS-202606-0012 | B13: Apex Industrial Supply | C13: INV-172574 | D13: 338.62 | E13: HR | F13: Non-PO | H13: Ava Johnson | I13: Department Manager | J13: 46163 | K13: Net 30 | L13: 46193 | M13: Paid | N13: None | O13: 46166 | P13: 46173 | Q13: =IF(J13="","",TODAY()-J13) -> 26 | R13: =IF(O13="","",O13-J13) -> 3 | S13: =IF(L13="","",L13-TODAY()) -> 4 | T13: =IF(AND(M13="Pending Approval",Q13>5),"Overdue","On Track") -> On Track | U13: =IF(AND(M13<>"Paid",S13<=5),"At Risk","Normal") -> Normal | V13: Payment completed
A14: NS-202606-0013 | B14: Ridgeway Plastics | C14: INV-781446 | D14: 2412.53 | E14: Procurement | F14: PO | G14: PO-47370 | H14: Nina Patel | I14: Department Manager | J14: 46177 | K14: 2/10 Net 30 | L14: 46207 | M14: Sent to Accounting | N14: Unclear Department Ownership | O14: 46189 | Q14: =IF(J14="","",TODAY()-J14) -> 12 | R14: =IF(O14="","",O14-J14) -> 12 | S14: =IF(L14="","",L14-TODAY()) -> 18 | T14: =IF(AND(M14="Pending Approval",Q14>5),"Overdue","On Track") -> On Track | U14: =IF(AND(M14<>"Paid",S14<=5),"At Risk","Normal") -> Normal | V14: Exception review required: Unclear Department Ownership
A15: NS-202606-0014 | B15: Lakeview Chemicals | C15: INV-174441 | D15: 13803.98 | E15: Facilities | F15: PO | G15: PO-34196 | H15: Victor Allen | I15: Director | J15: 46165 | K15: Net 15 | L15: 46180 | M15: Paid | N15: None | O15: 46172 | P15: 46187 | Q15: =IF(J15="","",TODAY()-J15) -> 24 | R15: =IF(O15="","",O15-J15) -> 7 | S15: =IF(L15="","",L15-TODAY()) -> -9 | T15: =IF(AND(M15="Pending Approval",Q15>5),"Overdue","On Track") -> On Track | U15: =IF(AND(M15<>"Paid",S15<=5),"At Risk","Normal") -> Normal | V15: Paid late due to approval bottleneck
A16: NS-202606-0015 | B16: WestBridge Staffing | C16: INV-858490 | D16: 556.67 | E16: Finance | F16: PO | G16: PO-51654 | H16: Evelyn Carter | I16: Department Manager | J16: 46148 | K16: Net 30 | L16: 46178 | M16: Paid | N16: None | O16: 46156 | P16: 46158 | Q16: =IF(J16="","",TODAY()-J16) -> 41 | R16: =IF(O16="","",O16-J16) -> 8 | S16: =IF(L16="","",L16-TODAY()) -> -11 | T16: =IF(AND(M16="Pending Approval",Q16>5),"Overdue","On Track") -> On Track | U16: =IF(AND(M16<>"Paid",S16<=5),"At Risk","Normal") -> Normal | V16: Payment completed
A17: NS-202606-0016 | B17: Summit Security | C17: INV-156802 | D17: 3820.02 | E17: HR | F17: Non-PO | H17: Ava Johnson | I17: Department Manager | J17: 46156 | K17: Net 15 | L17: 46171 | M17: Paid | N17: None | O17: 46167 | P17: 46173 | Q17: =IF(J17="","",TODAY()-J17) -> 33 | R17: =IF(O17="","",O17-J17) -> 11 | S17: =IF(L17="","",L17-TODAY()) -> -18 | T17: =IF(AND(M17="Pending Approval",Q17>5),"Overdue","On Track") -> On Track | U17: =IF(AND(M17<>"Paid",S17<=5),"At Risk","Normal") -> Normal | V17: Payment completed
A18: NS-202606-0017 | B18: Vector Calibration | C18: INV-392075 | D18: 32340.04 | E18: Finance | F18: PO | G18: PO-52236 | H18: Jordan Blake | I18: Finance Director | J18: 46150 | K18: Net 30 | L18: 46180 | M18: Paid | N18: None | O18: 46162 | P18: 46164 | Q18: =IF(J18="","",TODAY()-J18) -> 39 | R18: =IF(O18="","",O18-J18) -> 12 | S18: =IF(L18="","",L18-TODAY()) -> -9 | T18: =IF(AND(M18="Pending Approval",Q18>5),"Overdue","On Track") -> On Track | U18: =IF(AND(M18<>"Paid",S18<=5),"At Risk","Normal") -> Normal | V18: Payment completed
A19: NS-202606-0018 | B19: Orion Consulting | C19: INV-989921 | D19: 6470.01 | E19: Production | F19: Non-PO | H19: Heather King | I19: Director | J19: 46179 | K19: Net 15 | L19: 46194 | M19: Exception | N19: None | Q19: =IF(J19="","",TODAY()-J19) -> 10 | R19: =IF(O19="","",O19-J19) | S19: =IF(L19="","",L19-TODAY()) -> 5 | T19: =IF(AND(M19="Pending Approval",Q19>5),"Overdue","On Track") -> On Track | U19: =IF(AND(M19<>"Paid",S19<=5),"At Risk","Normal") -> At Risk
A20: NS-202606-0019 | B20: Harbor Freight Services | C20: INV-865990 | D20: 2440.18 | E20: Procurement | F20: Non-PO | H20: Nina Patel | I20: Department Manager | J20: 46147 | K20: Net 30 | L20: 46177 | M20: Paid | N20: None | O20: 46156 | P20: 46162 | Q20: =IF(J20="","",TODAY()-J20) -> 42 | R20: =IF(O20="","",O20-J20) -> 9 | S20: =IF(L20="","",L20-TODAY()) -> -12 | T20: =IF(AND(M20="Pending Approval",Q20>5),"Overdue","On Track") -> On Track | U20: =IF(AND(M20<>"Paid",S20<=5),"At Risk","Normal") -> Normal | V20: Payment completed
A21: NS-202606-0020 | B21: Ridgeway Plastics | C21: INV-627276 | D21: 954.33 | E21: Finance | F21: PO | G21: PO-33832 | H21: Evelyn Carter | I21: Department Manager | J21: 46181 | K21: Net 15 | L21: 46196 | M21: Paid | N21: None | O21: 46182 | P21: 46186 | Q21: =IF(J21="","",TODAY()-J21) -> 8 | R21: =IF(O21="","",O21-J21) -> 1 | S21: =IF(L21="","",L21-TODAY()) -> 7 | T21: =IF(AND(M21="Pending Approval",Q21>5),"Overdue","On Track") -> On Track | U21: =IF(AND(M21<>"Paid",S21<=5),"At Risk","Normal") -> Normal | V21: Payment completed
A22: NS-202606-0021 | B22: Quarry Equipment Rental | C22: INV-749468 | D22: 2560.62 | E22: Procurement | F22: Non-PO | H22: Nina Patel | I22: Department Manager | J22: 46148 | K22: Net 15 | L22: 46163 | M22: Paid | N22: None | O22: 46152 | P22: 46153 | Q22: =IF(J22="","",TODAY()-J22) -> 41 | R22: =IF(O22="","",O22-J22) -> 4 | S22: =IF(L22="","",L22-TODAY()) -> -26 | T22: =IF(AND(M22="Pending Approval",Q22>5),"Overdue","On Track") -> On Track | U22: =IF(AND(M22<>"Paid",S22<=5),"At Risk","Normal") -> Normal | V22: Payment completed
A23: NS-202606-0022 | B23: Cedar Packaging Co. | C23: INV-414569 | D23: 2821.78 | E23: Engineering | F23: PO | G23: PO-47089 | H23: Maya Singh | I23: Department Manager | J23: 46157 | K23: Net 45 | L23: 46202 | M23: Paid | N23: None | O23: 46164 | P23: 46170 | Q23: =IF(J23="","",TODAY()-J23) -> 32 | R23: =IF(O23="","",O23-J23) -> 7 | S23: =IF(L23="","",L23-TODAY()) -> 13 | T23: =IF(AND(M23="Pending Approval",Q23>5),"Overdue","On Track") -> On Track | U23: =IF(AND(M23<>"Paid",S23<=5),"At Risk","Normal") -> Normal | V23: Payment completed
A24: NS-202606-0023 | B24: Orion Consulting | C24: INV-238890 | D24: 23246.82 | E24: Logistics | F24: PO | G24: PO-70708 | H24: Anthony Ross | I24: Director | J24: 46180 | K24: Net 15 | L24: 46195 | M24: Approved | N24: None | O24: 46184 | Q24: =IF(J24="","",TODAY()-J24) -> 9 | R24: =IF(O24="","",O24-J24) -> 4 | S24: =IF(L24="","",L24-TODAY()) -> 6 | T24: =IF(AND(M24="Pending Approval",Q24>5),"Overdue","On Track") -> On Track | U24: =IF(AND(M24<>"Paid",S24<=5),"At Risk","Normal") -> Normal
A25: NS-202606-0024 | B25: Lakeview Chemicals | C25: INV-681542 | D25: 12205.78 | E25: Maintenance | F25: PO | G25: PO-84640 | H25: Priya Shah | I25: Director | J25: 46178 | K25: Net 45 | L25: 46223 | M25: Pending Approval | N25: None | Q25: =IF(J25="","",TODAY()-J25) -> 11 | R25: =IF(O25="","",O25-J25) | S25: =IF(L25="","",L25-TODAY()) -> 34 | T25: =IF(AND(M25="Pending Approval",Q25>5),"Overdue","On Track") -> Overdue | U25: =IF(AND(M25<>"Paid",S25<=5),"At Risk","Normal") -> Normal | V25: Awaiting manager/director action
A26: NS-202606-0025 | B26: Juniper Office Supply | C26: INV-820892 | D26: 4245.48 | E26: Finance | F26: PO | G26: PO-88308 | H26: Evelyn Carter | I26: Department Manager | J26: 46150 | K26: Net 30 | L26: 46180 | M26: Paid | N26: None | O26: 46154 | P26: 46182 | Q26: =IF(J26="","",TODAY()-J26) -> 39 | R26: =IF(O26="","",O26-J26) -> 4 | S26: =IF(L26="","",L26-TODAY()) -> -9 | T26: =IF(AND(M26="Pending Approval",Q26>5),"Overdue","On Track") -> On Track | U26: =IF(AND(M26<>"Paid",S26<=5),"At Risk","Normal") -> Normal | V26: Paid late due to approval bottleneck
A27: NS-202606-0026 | B27: Union Energy Services | C27: INV-768061 | D27: 1392.6 | E27: Quality | F27: Non-PO | H27: Lena Ortiz | I27: Department Manager | J27: 46147 | K27: Net 15 | L27: 46162 | M27: Paid | N27: None | O27: 46149 | P27: 46151 | Q27: =IF(J27="","",TODAY()-J27) -> 42 | R27: =IF(O27="","",O27-J27) -> 2 | S27: =IF(L27="","",L27-TODAY()) -> -27 | T27: =IF(AND(M27="Pending Approval",Q27>5),"Overdue","On Track") -> On Track | U27: =IF(AND(M27<>"Paid",S27<=5),"At Risk","Normal") -> Normal | V27: Payment completed
A28: NS-202606-0027 | B28: IronGate Components | C28: INV-710805 | D28: 15757.77 | E28: Procurement | F28: PO | G28: PO-30633 | H28: Carlos Mendes | I28: Director | J28: 46151 | K28: Net 15 | L28: 46166 | M28: Paid | N28: Unclear Department Ownership | O28: 46161 | P28: 46164 | Q28: =IF(J28="","",TODAY()-J28) -> 38 | R28: =IF(O28="","",O28-J28) -> 10 | S28: =IF(L28="","",L28-TODAY()) -> -23 | T28: =IF(AND(M28="Pending Approval",Q28>5),"Overdue","On Track") -> On Track | U28: =IF(AND(M28<>"Paid",S28<=5),"At Risk","Normal") -> Normal | V28: Exception review required: Unclear Department Ownership
A29: NS-202606-0028 | B29: Ridgeway Plastics | C29: INV-918011 | D29: 440.32 | E29: Procurement | F29: PO | G29: PO-82174 | H29: Nina Patel | I29: Department Manager | J29: 46146 | K29: Net 45 | L29: 46191 | M29: Paid | N29: None | O29: 46150 | P29: 46153 | Q29: =IF(J29="","",TODAY()-J29) -> 43 | R29: =IF(O29="","",O29-J29) -> 4 | S29: =IF(L29="","",L29-TODAY()) -> 2 | T29: =IF(AND(M29="Pending Approval",Q29>5),"Overdue","On Track") -> On Track | U29: =IF(AND(M29<>"Paid",S29<=5),"At Risk","Normal") -> Normal | V29: Payment completed
A30: NS-202606-0029 | B30: Ridgeway Plastics | C30: INV-920391 | D30: 77588.69 | E30: Engineering | F30: Non-PO | H30: Jordan Blake | I30: Finance Director | J30: 46159 | K30: Net 30 | L30: 46189 | M30: Paid | N30: Unclear Department Ownership | O30: 46173 | P30: 46176 | Q30: =IF(J30="","",TODAY()-J30) -> 30 | R30: =IF(O30="","",O30-J30) -> 14 | S30: =IF(L30="","",L30-TODAY()) -> 0 | T30: =IF(AND(M30="Pending Approval",Q30>5),"Overdue","On Track") -> On Track | U30: =IF(AND(M30<>"Paid",S30<=5),"At Risk","Normal") -> Normal | V30: Exception review required: Unclear Department Ownership
A31: NS-202606-0030 | B31: Northfield Metals | C31: INV-333238 | D31: 20809.61 | E31: Finance | F31: PO | G31: PO-81601 | H31: Finance Director | I31: Director | J31: 46188 | K31: Net 15 | L31: 46203 | M31: Approved | N31: None | O31: 46189 | Q31: =IF(J31="","",TODAY()-J31) -> 1 | R31: =IF(O31="","",O31-J31) -> 1 | S31: =IF(L31="","",L31-TODAY()) -> 14 | T31: =IF(AND(M31="Pending Approval",Q31>5),"Overdue","On Track") -> On Track | U31: =IF(AND(M31<>"Paid",S31<=5),"At Risk","Normal") -> Normal
A32: NS-202606-0031 | B32: Granite Safety Supply | C32: INV-392683 | D32: 3983.44 | E32: Facilities | F32: Non-PO | H32: Grace Morgan | I32: Department Manager | J32: 46158 | K32: Net 15 | L32: 46173 | M32: Exception | N32: None | Q32: =IF(J32="","",TODAY()-J32) -> 31 | R32: =IF(O32="","",O32-J32) | S32: =IF(L32="","",L32-TODAY()) -> -16 | T32: =IF(AND(M32="Pending Approval",Q32>5),"Overdue","On Track") -> On Track | U32: =IF(AND(M32<>"Paid",S32<=5),"At Risk","Normal") -> At Risk
A33: NS-202606-0032 | B33: Lakeview Chemicals | C33: INV-555673 | D33: 3341.81 | E33: Finance | F33: Non-PO | H33: Evelyn Carter | I33: Department Manager | J33: 46165 | K33: Net 15 | L33: 46180 | M33: Paid | N33: None | O33: 46171 | P33: 46176 | Q33: =IF(J33="","",TODAY()-J33) -> 24 | R33: =IF(O33="","",O33-J33) -> 6 | S33: =IF(L33="","",L33-TODAY()) -> -9 | T33: =IF(AND(M33="Pending Approval",Q33>5),"Overdue","On Track") -> On Track | U33: =IF(AND(M33<>"Paid",S33<=5),"At Risk","Normal") -> Normal | V33: Payment completed
A34: NS-202606-0033 | B34: Lakeview Chemicals | C34: INV-645175 | D34: 13509.68 | E34: Sales | F34: Non-PO | H34: Michelle Young | I34: Director | J34: 46151 | K34: 2/10 Net 30 | L34: 46181 | M34: Paid | N34: Incorrect Vendor Information | O34: 46161 | P34: 46162 | Q34: =IF(J34="","",TODAY()-J34) -> 38 | R34: =IF(O34="","",O34-J34) -> 10 | S34: =IF(L34="","",L34-TODAY()) -> -8 | T34: =IF(AND(M34="Pending Approval",Q34>5),"Overdue","On Track") -> On Track | U34: =IF(AND(M34<>"Paid",S34<=5),"At Risk","Normal") -> Normal | V34: Exception review required: Incorrect Vendor Information
A35: NS-202606-0034 | B35: Ridgeway Plastics | C35: INV-854717 | D35: 3625.87 | E35: Finance | F35: Non-PO | H35: Evelyn Carter | I35: Department Manager | J35: 46167 | K35: 2/10 Net 30 | L35: 46197 | M35: Paid | N35: None | O35: 46176 | P35: 46177 | Q35: =IF(J35="","",TODAY()-J35) -> 22 | R35: =IF(O35="","",O35-J35) -> 9 | S35: =IF(L35="","",L35-TODAY()) -> 8 | T35: =IF(AND(M35="Pending Approval",Q35>5),"Overdue","On Track") -> On Track | U35: =IF(AND(M35<>"Paid",S35<=5),"At Risk","Normal") -> Normal | V35: Payment completed
A36: NS-202606-0035 | B36: Juniper Office Supply | C36: INV-282480 | D36: 2108.19 | E36: IT | F36: PO | G36: PO-49376 | H36: Noah Bennett | I36: Department Manager | J36: 46179 | K36: Net 30 | L36: 46209 | M36: Pending Approval | N36: None | Q36: =IF(J36="","",TODAY()-J36) -> 10 | R36: =IF(O36="","",O36-J36) | S36: =IF(L36="","",L36-TODAY()) -> 20 | T36: =IF(AND(M36="Pending Approval",Q36>5),"Overdue","On Track") -> Overdue | U36: =IF(AND(M36<>"Paid",S36<=5),"At Risk","Normal") -> Normal | V36: Awaiting manager/director action
A37: NS-202606-0036 | B37: Titan Machine Parts | C37: INV-808446 | D37: 2743.11 | E37: HR | F37: PO | G37: PO-48803 | H37: Ava Johnson | I37: Department Manager | J37: 46157 | K37: 2/10 Net 30 | L37: 46187 | M37: Paid | N37: None | O37: 46163 | P37: 46167 | Q37: =IF(J37="","",TODAY()-J37) -> 32 | R37: =IF(O37="","",O37-J37) -> 6 | S37: =IF(L37="","",L37-TODAY()) -> -2 | T37: =IF(AND(M37="Pending Approval",Q37>5),"Overdue","On Track") -> On Track | U37: =IF(AND(M37<>"Paid",S37<=5),"At Risk","Normal") -> Normal | V37: Payment completed
A38: NS-202606-0037 | B38: Granite Safety Supply | C38: INV-887625 | D38: 4350.37 | E38: IT | F38: Non-PO | H38: Noah Bennett | I38: Department Manager | J38: 46154 | K38: Net 15 | L38: 46169 | M38: Sent to Accounting | N38: None | O38: 46161 | Q38: =IF(J38="","",TODAY()-J38) -> 35 | R38: =IF(O38="","",O38-J38) -> 7 | S38: =IF(L38="","",L38-TODAY()) -> -20 | T38: =IF(AND(M38="Pending Approval",Q38>5),"Overdue","On Track") -> On Track | U38: =IF(AND(M38<>"Paid",S38<=5),"At Risk","Normal") -> At Risk
A39: NS-202606-0038 | B39: Harbor Freight Services | C39: INV-703634 | D39: 3919.86 | E39: Finance | F39: PO | G39: PO-33028 | H39: Evelyn Carter | I39: Department Manager | J39: 46159 | K39: 2/10 Net 30 | L39: 46189 | M39: Paid | N39: None | O39: 46161 | P39: 46194 | Q39: =IF(J39="","",TODAY()-J39) -> 30 | R39: =IF(O39="","",O39-J39) -> 2 | S39: =IF(L39="","",L39-TODAY()) -> 0 | T39: =IF(AND(M39="Pending Approval",Q39>5),"Overdue","On Track") -> On Track | U39: =IF(AND(M39<>"Paid",S39<=5),"At Risk","Normal") -> Normal | V39: Paid late due to approval bottleneck
A40: NS-202606-0039 | B40: Granite Safety Supply | C40: INV-284430 | D40: 2499.42 | E40: Sales | F40: PO | G40: PO-72995 | H40: Ryan Scott | I40: Department Manager | J40: 46188 | K40: Net 15 | L40: 46203 | M40: Pending Approval | N40: Incorrect Vendor Information | Q40: =IF(J40="","",TODAY()-J40) -> 1 | R40: =IF(O40="","",O40-J40) | S40: =IF(L40="","",L40-TODAY()) -> 14 | T40: =IF(AND(M40="Pending Approval",Q40>5),"Overdue","On Track") -> On Track | U40: =IF(AND(M40<>"Paid",S40<=5),"At Risk","Normal") -> Normal | V40: Exception review required: Incorrect Vendor Information
...

Sheet Lists
A1: Status | B1: Exception Type | C1: Invoice Type | D1: Payment Terms | E1: Department | F1: Approval Level
A2: Paid | B2: None | C2: PO | D2: Net 15 | E2: Operations | F2: Department Manager
A3: Sent to Accounting | B3: Missing PO | C3: Non-PO | D3: Net 30 | E3: Maintenance | F3: Director
A4: Approved | B4: Missing Documentation | D4: Net 45 | E4: Procurement | F4: Finance Director
A5: Pending Approval | B5: Incorrect Vendor Information | D5: 2/10 Net 30 | E5: Production
A6: Exception | B6: Duplicate Invoice | E6: Quality
A7: Rejected | B7: Unclear Department Ownership | E7: Logistics
E8: Engineering
E9: Facilities
E10: IT
E11: HR
E12: Finance
E13: Sales

Sheet KPI Dashboard
A1: NorthStar Manufacturing — Invoice Approval KPI Dashboard
A2: Dataset regenerated to align with case story: 1,200 invoices/month, ~60% PO, ~40% Non-PO, approval delays, late payment risk, and exception-driven rework.
A4: Metric | B4: Value | C4: Interpretation | E4: Approver | F4: Open Invoices | G4: Overdue Approvals | H4: Late Payment Risk | J4: Department | K4: Approved Count | L4: Avg Cycle Days | M4: Non-PO Count | O4: Exception Type | P4: Count
A5: Total Invoices | B5: =COUNTA('Invoice Tracker'!A2:A1201) -> 1200 | C5: Monthly invoice volume | E5: Lena Ortiz | F5: 45 | G5: 10 | H5: 10 | J5: Maintenance | K5: 85 | L5: 10.105882 | M5: 47 | O5: Unclear Department Ownership | P5: 124
A6: PO-Backed % | B6: =COUNTIF('Invoice Tracker'!F2:F1201,"PO")/COUNTA('Invoice Tracker'!A2:A1201) -> 0.605 | C6: Target story alignment: about 60% | E6: Marcus Lee | F6: 45 | G6: 11 | H6: 9 | J6: Production | K6: 64 | L6: 9.875 | M6: 40 | O6: Missing Documentation | P6: 114
A7: Non-PO % | B7: =COUNTIF('Invoice Tracker'!F2:F1201,"Non-PO")/COUNTA('Invoice Tracker'!A2:A1201) -> 0.395 | C7: Manual review exposure | E7: Grace Morgan | F7: 44 | G7: 9 | H7: 10 | J7: Facilities | K7: 79 | L7: 8.4177215 | M7: 43 | O7: Missing PO | P7: 59
A8: Open Invoices | B8: =COUNTIFS('Invoice Tracker'!M2:M1201,"<>Paid",'Invoice Tracker'!M2:M1201,"<>Rejected") -> 611 | C8: Current AP/approval backlog | E8: Jordan Blake | F8: 42 | G8: 6 | H8: 11 | J8: Operations | K8: 64 | L8: 8.40625 | M8: 34 | O8: Incorrect Vendor Information | P8: 37
A9: Overdue Approvals | B9: =COUNTIF('Invoice Tracker'!T2:T1201,"Overdue") -> 155 | C9: Approval SLA risk | E9: Ethan Brooks | F9: 41 | G9: 10 | H9: 12 | J9: IT | K9: 65 | L9: 7.9846154 | M9: 40 | O9: Duplicate Invoice | P9: 21
A10: Late Payment Risk | B10: =COUNTIF('Invoice Tracker'!U2:U1201,"At Risk") -> 154 | C10: Invoices near/past due and unpaid | E10: Noah Bennett | F10: 41 | G10: 12 | H10: 10 | J10: Engineering | K10: 75 | L10: 7.7866667 | M10: 38
A11: Late Paid Invoices | B11: =COUNTIF('Invoice Tracker'!#REF!,"Late") -> #REF! | C11: Confirmed late payments | E11: Tyler Chen | F11: 41 | G11: 13 | H11: 10 | J11: Finance | K11: 61 | L11: 7.6229508 | M11: 39
A12: Exception Rate | B12: =COUNTIF('Invoice Tracker'!N2:N1201,"<>None")/COUNTA('Invoice Tracker'!A2:A1201) -> 0.29583333 | C12: Rework/control risk | E12: Olivia Grant | F12: 41 | G12: 11 | H12: 6 | J12: Sales | K12: 81 | L12: 7.2592593 | M12: 44
A13: Avg Approval Cycle Days | B13: =AVERAGE('Invoice Tracker'!R2:R1201) -> 7.9584816 | C13: Receipt to approval | E13: Ava Johnson | F13: 37 | G13: 10 | H13: 13 | J13: Logistics | K13: 69 | L13: 7.0869565 | M13: 35
E14: Evelyn Carter | F14: 31 | G14: 7 | H14: 7 | J14: Procurement | K14: 69 | L14: 7.0289855 | M14: 38
J15: Quality | K15: 67 | L15: 6.9701493 | M15: 38
J16: HR | K16: 64 | L16: 6.53125 | M16: 38

Sheet Approval Matrix
A1: Department | B1: Department Manager | C1: Director | D1: < $5,000 | E1: $5,000-$25,000 | F1: > $25,000 | G1: Backup Approver | H1: Last Reviewed
A2: Operations | B2: Olivia Grant | C2: Daniel Reed | D2: Olivia Grant | E2: Daniel Reed | F2: Jordan Blake | G2: Delegated Backup Required | H2: 46189
A3: Maintenance | B3: Marcus Lee | C3: Priya Shah | D3: Marcus Lee | E3: Priya Shah | F3: Jordan Blake | G3: Delegated Backup Required | H3: 46189
A4: Procurement | B4: Nina Patel | C4: Carlos Mendes | D4: Nina Patel | E4: Carlos Mendes | F4: Jordan Blake | G4: Delegated Backup Required | H4: 46189
A5: Production | B5: Ethan Brooks | C5: Heather King | D5: Ethan Brooks | E5: Heather King | F5: Jordan Blake | G5: Delegated Backup Required | H5: 46189
A6: Quality | B6: Lena Ortiz | C6: Samantha Wu | D6: Lena Ortiz | E6: Samantha Wu | F6: Jordan Blake | G6: Delegated Backup Required | H6: 46189
A7: Logistics | B7: Tyler Chen | C7: Anthony Ross | D7: Tyler Chen | E7: Anthony Ross | F7: Jordan Blake | G7: Delegated Backup Required | H7: 46189
A8: Engineering | B8: Maya Singh | C8: Robert Hayes | D8: Maya Singh | E8: Robert Hayes | F8: Jordan Blake | G8: Delegated Backup Required | H8: 46189
A9: Facilities | B9: Grace Morgan | C9: Victor Allen | D9: Grace Morgan | E9: Victor Allen | F9: Jordan Blake | G9: Delegated Backup Required | H9: 46189
A10: IT | B10: Noah Bennett | C10: Monica Price | D10: Noah Bennett | E10: Monica Price | F10: Jordan Blake | G10: Delegated Backup Required | H10: 46189
A11: HR | B11: Ava Johnson | C11: Karen Lewis | D11: Ava Johnson | E11: Karen Lewis | F11: Jordan Blake | G11: Delegated Backup Required | H11: 46189
A12: Finance | B12: Evelyn Carter | C12: Finance Director | D12: Evelyn Carter | E12: Finance Director | F12: Jordan Blake | G12: Delegated Backup Required | H12: 46189
A13: Sales | B13: Ryan Scott | C13: Michelle Young | D13: Ryan Scott | E13: Michelle Young | F13: Jordan Blake | G13: Delegated Backup Required | H13: 46189

Sheet Exception Log
A1: Exception Type | B1: Invoice Count | C1: % of Total | D1: Primary Risk | E1: Recommended Action
A2: Unclear Department Ownership | B2: 124 | C2: 0.10333333 | D2: Routing delay risk | E2: Update department ownership in approval matrix.
A3: Missing Documentation | B3: 114 | C3: 0.095 | D3: Audit evidence risk | E3: Require supporting docs before approval task is issued.
A4: Missing PO | B4: 59 | C4: 0.049166667 | D4: Control / validation risk | E4: Require PO before routing or document approved non-PO exception.
A5: Incorrect Vendor Information | B5: 37 | C5: 0.030833333 | D5: Payment accuracy risk | E5: Validate vendor master data before approval.
A6: Duplicate Invoice | B6: 21 | C6: 0.0175 | D6: Duplicate payment risk | E6: Apply vendor + invoice number duplicate check.

Sheet Business Requirements
A1: ID | B1: Type | C1: Requirement | D1: Priority | E1: Release
A2: BR-1 | B2: Business | C2: Reduce manual AP coordination effort | D2: High | E2: MVP
A3: BR-2 | B3: Business | C3: Improve visibility into invoice status and approval aging | D3: High | E3: MVP
A4: BR-3 | B4: Business | C4: Reduce approval delays and late payment risk | D4: High | E4: MVP
A5: BR-4 | B5: Business | C5: Support approval rules based on department ownership and invoice amount | D5: High | E5: MVP
A6: BR-5 | B6: Business | C6: Support additional review for non-PO invoices | D6: High | E6: MVP
A7: BR-6 | B7: Business | C7: Improve audit readiness and evidence retrieval | D7: High | E7: Phase 2
A8: BR-7 | B8: Functional | C8: Capture vendor, invoice number, amount, department, approver, dates, status, exception, and comments | D8: High | E8: MVP
A9: BR-8 | B9: Functional | C9: Route invoices under $5,000 to Department Manager | D9: High | E9: Phase 2
A10: BR-9 | B10: Functional | C10: Route invoices from $5,000 to $25,000 to Director | D10: High | E10: Phase 2
A11: BR-10 | B11: Functional | C11: Route invoices over $25,000 to Finance Director | D11: High | E11: Phase 2
A12: BR-11 | B12: Functional | C12: Send automated reminders and escalations for overdue approvals | D12: High | E12: Phase 2
A13: BR-12 | B13: Non-Functional | C13: Use role-based access and maintain auditable approval history | D13: High | E13: Phase 2

Sheet User Stories
A1: ID | B1: Release | C1: User Role | D1: Capability | E1: Business Value | F1: Acceptance Criteria
A2: US-1 | B2: MVP | C2: AP Analyst | D2: Standardized invoice tracker | E2: Track invoice status, aging, and ownership consistently | F2: Tracker includes required fields; status values standardized; overdue invoices flagged; exception reason captured
A3: US-2 | B3: MVP | C3: AP Analyst | D3: Updated approval matrix | E3: Route invoices without repeated clarification | F3: Matrix includes department, manager, director, backup approver, thresholds, owner, and review date
A4: US-3 | B4: MVP | C4: Finance Manager | D4: Approval SLA | E4: Identify overdue approvals and create accountability | F4: SLA start point documented; overdue logic defined; escalation timing documented
A5: US-4 | B5: MVP | C5: Finance Director | D5: Weekly aging report | E5: See pending invoices, overdue approvals, and late payment risk | F5: Report shows pending invoices by approver, department, age, amount, and due date
A6: US-5 | B6: Phase 2 | C6: AP Analyst | D6: Automated routing | E6: Reduce time spent determining approvers | F6: Invoices route by department and amount; non-PO invoices flagged
A7: US-6 | B7: Phase 2 | C7: AP Analyst | D7: Automated reminders | E7: Reduce manual follow-up effort | F7: Reminders sent by SLA; reminder history visible
A8: US-7 | B8: Phase 2 | C8: Finance Manager | D8: Escalation workflow | E8: Prevent approvals from remaining stuck | F8: Escalations occur after overdue thresholds and are visible in reporting
A9: US-8 | B9: Phase 2 | C9: Auditor | D9: Approval audit trail | E9: Retrieve approval evidence efficiently | F9: Approval includes approver, date, decision, comments, supporting docs, and retention
A10: US-9 | B10: Future | C10: Finance Leadership | D10: Dynamics 365 workflow assessment | E10: Determine if ERP can support future-state workflow | F10: Workflow options, integration points, support needs, cost, and effort documented

Sheet Implementation Roadmap
A1: Phase | B1: Timeline | C1: Focus | D1: Key Activities | E1: Deliverables
A2: Phase 1 | B2: Days 1-30 | C2: Standardize and Stabilize | D2: Update approval policy; validate approval matrix; standardize tracker; define exceptions | E2: Updated policy, approval matrix, tracker, exception code list
A3: Phase 1 | B3: Days 31-60 | C3: Visibility and Accountability | D3: Define SLA; build aging report; establish KPI baseline; communicate manager expectations | E3: Approval SLA, weekly aging report, KPI baseline
A4: Phase 2 | B4: Days 61-90 | C4: Automation Preparation | D4: Document workflow requirements; define reminder/escalation rules; test pilot design | E4: Workflow requirements, test scenarios, pilot plan
A5: Phase 2 | B5: Days 91-150 | C5: Workflow Automation | D5: Configure routing, approval queue, reminders, escalations, audit trail, dashboard | E5: Automated workflow and dashboard
A6: Phase 3 | B6: Days 151+ | C6: Long-Term Platform Decision | D6: Assess Dynamics 365 workflow vs AP automation software | E6: Feasibility assessment, solution recommendation, implementation roadmap

Sheet Data Dictionary
A1: Field | B1: Definition
A2: Invoice ID | B2: Unique invoice tracking ID for the simulated NorthStar monthly dataset
A3: Invoice Amount | B3: Vendor invoice dollar value
A4: Invoice Type | B4: PO or Non-PO; target story alignment is approximately 60% PO and 40% Non-PO
A5: Approval Level | B5: Approver authority based on amount threshold
A6: Invoice Age Days | B6: Formula: TODAY() - Date Received
A7: Approval Cycle Days | B7: Formula: Approval Date - Date Received when approved
A8: Days Until Due | B8: Formula: Payment Due Date - TODAY()
A9: Overdue Approval Flag | B9: Formula-based flag when invoice is pending approval and older than SLA threshold
A10: Late Payment Risk | B10: Formula-based flag for unpaid invoices due within five days or past due
A11: Exception Type | B11: Common rework/control issue: Missing PO, Missing Documentation, Incorrect Vendor Information, Duplicate Invoice, Unclear Department Ownership
